Exception in thread Thread-1:
Traceback (most recent call last):
  File "/usr/lib/python3.8/threading.py", line 932, in _bootstrap_inner
    self.run()
  File "/home/user/frappe-bench/env/lib/python3.8/site-packages/redis/client.py", line 3718, in run
    pubsub.get_message(ignore_subscribe_messages=True,
  File "/home/user/frappe-bench/env/lib/python3.8/site-packages/redis/client.py", line 3617, in get_message
Exception in thread Thread-1:
Traceback (most recent call last):
  File "/usr/lib/python3.8/threading.py", line 932, in _bootstrap_inner
    self.run()
  File "/home/user/frappe-bench/env/lib/python3.8/site-packages/redis/client.py", line 3718, in run
    response = self.parse_response(block=False, timeout=timeout)
  File "/home/user/frappe-bench/env/lib/python3.8/site-packages/redis/client.py", line 3503, in parse_response
    pubsub.get_message(ignore_subscribe_messages=True,
  File "/home/user/frappe-bench/env/lib/python3.8/site-packages/redis/client.py", line 3617, in get_message
    if not block and not conn.can_read(timeout=timeout):
  File "/home/user/frappe-bench/env/lib/python3.8/site-packages/redis/connection.py", line 734, in can_read
    return self._parser.can_read(timeout)
  File "/home/user/frappe-bench/env/lib/python3.8/site-packages/redis/connection.py", line 321, in can_read
    return self._buffer and self._buffer.can_read(timeout)
  File "/home/user/frappe-bench/env/lib/python3.8/site-packages/redis/connection.py", line 230, in can_read
    self._read_from_socket(timeout=timeout,
  File "/home/user/frappe-bench/env/lib/python3.8/site-packages/redis/connection.py", line 201, in _read_from_socket
    response = self.parse_response(block=False, timeout=timeout)
  File "/home/user/frappe-bench/env/lib/python3.8/site-packages/redis/client.py", line 3503, in parse_response
    raise ConnectionError(SERVER_CLOSED_CONNECTION_ERROR)
redis.exceptions.ConnectionError: Connection closed by server.
    if not block and not conn.can_read(timeout=timeout):
  File "/home/user/frappe-bench/env/lib/python3.8/site-packages/redis/connection.py", line 734, in can_read
    return self._parser.can_read(timeout)
  File "/home/user/frappe-bench/env/lib/python3.8/site-packages/redis/connection.py", line 321, in can_read
    return self._buffer and self._buffer.can_read(timeout)
  File "/home/user/frappe-bench/env/lib/python3.8/site-packages/redis/connection.py", line 230, in can_read
    self._read_from_socket(timeout=timeout,
  File "/home/user/frappe-bench/env/lib/python3.8/site-packages/redis/connection.py", line 201, in _read_from_socket
    raise ConnectionError(SERVER_CLOSED_CONNECTION_ERROR)
redis.exceptions.ConnectionError: Connection closed by server.
19:55:55 Traceback (most recent call last):
  File "/home/user/frappe-bench/env/lib/python3.8/site-packages/rq/worker.py", line 1013, in perform_job
    rv = job.perform()
  File "/home/user/frappe-bench/env/lib/python3.8/site-packages/rq/job.py", line 709, in perform
    self._result = self._execute()
  File "/home/user/frappe-bench/env/lib/python3.8/site-packages/rq/job.py", line 732, in _execute
    result = self.func(*self.args, **self.kwargs)
  File "/home/user/frappe-bench/apps/frappe/frappe/utils/background_jobs.py", line 106, in execute_job
    method(**kwargs)
  File "/home/user/frappe-bench/apps/frappe/frappe/core/doctype/user/user.py", line 991, in create_contact
    contact.insert(ignore_permissions=True, ignore_links=ignore_links, ignore_mandatory=ignore_mandatory)
  File "/home/user/frappe-bench/apps/frappe/frappe/model/document.py", line 229, in insert
    self._validate_links()
  File "/home/user/frappe-bench/apps/frappe/frappe/model/document.py", line 827, in _validate_links
    frappe.throw(_("Could not find {0}").format(msg),
  File "/home/user/frappe-bench/apps/frappe/frappe/__init__.py", line 440, in throw
    msgprint(msg, raise_exception=exc, title=title, indicator='red', is_minimizable=is_minimizable, wide=wide, as_list=as_list)
  File "/home/user/frappe-bench/apps/frappe/frappe/__init__.py", line 419, in msgprint
    _raise_exception()
  File "/home/user/frappe-bench/apps/frappe/frappe/__init__.py", line 373, in _raise_exception
    raise raise_exception(msg)
frappe.exceptions.LinkValidationError: Could not find User Id: patelasif52@gmail.com

Exception in thread Thread-1:
Traceback (most recent call last):
  File "/usr/lib/python3.8/threading.py", line 932, in _bootstrap_inner
Exception in thread Thread-1:
Traceback (most recent call last):
  File "/usr/lib/python3.8/threading.py", line 932, in _bootstrap_inner
    self.run()
  File "/home/user/frappe-bench/env/lib/python3.8/site-packages/redis/client.py", line 3718, in run
    self.run()
  File "/home/user/frappe-bench/env/lib/python3.8/site-packages/redis/client.py", line 3718, in run
    pubsub.get_message(ignore_subscribe_messages=True,
  File "/home/user/frappe-bench/env/lib/python3.8/site-packages/redis/client.py", line 3617, in get_message
    pubsub.get_message(ignore_subscribe_messages=True,
  File "/home/user/frappe-bench/env/lib/python3.8/site-packages/redis/client.py", line 3617, in get_message
    response = self.parse_response(block=False, timeout=timeout)
  File "/home/user/frappe-bench/env/lib/python3.8/site-packages/redis/client.py", line 3503, in parse_response
    response = self.parse_response(block=False, timeout=timeout)
  File "/home/user/frappe-bench/env/lib/python3.8/site-packages/redis/client.py", line 3503, in parse_response
    if not block and not conn.can_read(timeout=timeout):
  File "/home/user/frappe-bench/env/lib/python3.8/site-packages/redis/connection.py", line 734, in can_read
    return self._parser.can_read(timeout)
  File "/home/user/frappe-bench/env/lib/python3.8/site-packages/redis/connection.py", line 321, in can_read
    if not block and not conn.can_read(timeout=timeout):
  File "/home/user/frappe-bench/env/lib/python3.8/site-packages/redis/connection.py", line 734, in can_read
    return self._buffer and self._buffer.can_read(timeout)
  File "/home/user/frappe-bench/env/lib/python3.8/site-packages/redis/connection.py", line 230, in can_read
    self._read_from_socket(timeout=timeout,
  File "/home/user/frappe-bench/env/lib/python3.8/site-packages/redis/connection.py", line 201, in _read_from_socket
        return self._parser.can_read(timeout)raise ConnectionError(SERVER_CLOSED_CONNECTION_ERROR)

  File "/home/user/frappe-bench/env/lib/python3.8/site-packages/redis/connection.py", line 321, in can_read
redis.exceptions.ConnectionError: Connection closed by server.
    return self._buffer and self._buffer.can_read(timeout)
  File "/home/user/frappe-bench/env/lib/python3.8/site-packages/redis/connection.py", line 230, in can_read
    self._read_from_socket(timeout=timeout,
  File "/home/user/frappe-bench/env/lib/python3.8/site-packages/redis/connection.py", line 201, in _read_from_socket
    raise ConnectionError(SERVER_CLOSED_CONNECTION_ERROR)
redis.exceptions.ConnectionError: Connection closed by server.
Exception in thread Thread-1:
Traceback (most recent call last):
  File "/usr/lib/python3.8/threading.py", line 932, in _bootstrap_inner
    self.run()
  File "/home/user/frappe-bench/env/lib/python3.8/site-packages/redis/client.py", line 3718, in run
    pubsub.get_message(ignore_subscribe_messages=True,
  File "/home/user/frappe-bench/env/lib/python3.8/site-packages/redis/client.py", line 3617, in get_message
    response = self.parse_response(block=False, timeout=timeout)
  File "/home/user/frappe-bench/env/lib/python3.8/site-packages/redis/client.py", line 3503, in parse_response
    if not block and not conn.can_read(timeout=timeout):
  File "/home/user/frappe-bench/env/lib/python3.8/site-packages/redis/connection.py", line 734, in can_read
    return self._parser.can_read(timeout)
  File "/home/user/frappe-bench/env/lib/python3.8/site-packages/redis/connection.py", line 321, in can_read
    return self._buffer and self._buffer.can_read(timeout)
  File "/home/user/frappe-bench/env/lib/python3.8/site-packages/redis/connection.py", line 230, in can_read
    self._read_from_socket(timeout=timeout,
  File "/home/user/frappe-bench/env/lib/python3.8/site-packages/redis/connection.py", line 201, in _read_from_socket
    raise ConnectionError(SERVER_CLOSED_CONNECTION_ERROR)
redis.exceptions.ConnectionError: Connection closed by server.
Exception in thread Thread-1:
Traceback (most recent call last):
  File "/usr/lib/python3.8/threading.py", line 932, in _bootstrap_inner
    self.run()
  File "/home/user/frappe-bench/env/lib/python3.8/site-packages/redis/client.py", line 3718, in run
    pubsub.get_message(ignore_subscribe_messages=True,
  File "/home/user/frappe-bench/env/lib/python3.8/site-packages/redis/client.py", line 3617, in get_message
    response = self.parse_response(block=False, timeout=timeout)
  File "/home/user/frappe-bench/env/lib/python3.8/site-packages/redis/client.py", line 3503, in parse_response
    if not block and not conn.can_read(timeout=timeout):
  File "/home/user/frappe-bench/env/lib/python3.8/site-packages/redis/connection.py", line 734, in can_read
    return self._parser.can_read(timeout)
  File "/home/user/frappe-bench/env/lib/python3.8/site-packages/redis/connection.py", line 321, in can_read
    return self._buffer and self._buffer.can_read(timeout)
  File "/home/user/frappe-bench/env/lib/python3.8/site-packages/redis/connection.py", line 230, in can_read
    self._read_from_socket(timeout=timeout,
  File "/home/user/frappe-bench/env/lib/python3.8/site-packages/redis/connection.py", line 201, in _read_from_socket
    raise ConnectionError(SERVER_CLOSED_CONNECTION_ERROR)
redis.exceptions.ConnectionError: Connection closed by server.
11:35:07 Traceback (most recent call last):
  File "/home/user/frappe-bench/env/lib/python3.8/site-packages/rq/worker.py", line 1013, in perform_job
    rv = job.perform()
  File "/home/user/frappe-bench/env/lib/python3.8/site-packages/rq/job.py", line 709, in perform
    self._result = self._execute()
  File "/home/user/frappe-bench/env/lib/python3.8/site-packages/rq/job.py", line 732, in _execute
    result = self.func(*self.args, **self.kwargs)
  File "/home/user/frappe-bench/apps/frappe/frappe/utils/background_jobs.py", line 106, in execute_job
    method(**kwargs)
  File "/home/user/frappe-bench/apps/frappe/frappe/core/doctype/user/user.py", line 991, in create_contact
    contact.insert(ignore_permissions=True, ignore_links=ignore_links, ignore_mandatory=ignore_mandatory)
  File "/home/user/frappe-bench/apps/frappe/frappe/model/document.py", line 229, in insert
    self._validate_links()
  File "/home/user/frappe-bench/apps/frappe/frappe/model/document.py", line 827, in _validate_links
    frappe.throw(_("Could not find {0}").format(msg),
  File "/home/user/frappe-bench/apps/frappe/frappe/__init__.py", line 440, in throw
    msgprint(msg, raise_exception=exc, title=title, indicator='red', is_minimizable=is_minimizable, wide=wide, as_list=as_list)
  File "/home/user/frappe-bench/apps/frappe/frappe/__init__.py", line 419, in msgprint
    _raise_exception()
  File "/home/user/frappe-bench/apps/frappe/frappe/__init__.py", line 373, in _raise_exception
    raise raise_exception(msg)
frappe.exceptions.LinkValidationError: Could not find User Id: shalini@gmail.com

Exception in thread Thread-1Exception in thread :
Thread-1:
Traceback (most recent call last):
Traceback (most recent call last):
  File "/usr/lib/python3.8/threading.py", line 932, in _bootstrap_inner
  File "/usr/lib/python3.8/threading.py", line 932, in _bootstrap_inner
Exception in thread Thread-1:
Traceback (most recent call last):
  File "/usr/lib/python3.8/threading.py", line 932, in _bootstrap_inner
    self.run()
  File "/home/user/frappe-bench/env/lib/python3.8/site-packages/redis/client.py", line 3718, in run
    self.run()
  File "/home/user/frappe-bench/env/lib/python3.8/site-packages/redis/client.py", line 3718, in run
    self.run()
  File "/home/user/frappe-bench/env/lib/python3.8/site-packages/redis/client.py", line 3718, in run
    pubsub.get_message(ignore_subscribe_messages=True,
  File "/home/user/frappe-bench/env/lib/python3.8/site-packages/redis/client.py", line 3617, in get_message
    response = self.parse_response(block=False, timeout=timeout)
  File "/home/user/frappe-bench/env/lib/python3.8/site-packages/redis/client.py", line 3503, in parse_response
    pubsub.get_message(ignore_subscribe_messages=True,
  File "/home/user/frappe-bench/env/lib/python3.8/site-packages/redis/client.py", line 3617, in get_message
    if not block and not conn.can_read(timeout=timeout):
  File "/home/user/frappe-bench/env/lib/python3.8/site-packages/redis/connection.py", line 734, in can_read
    response = self.parse_response(block=False, timeout=timeout)
  File "/home/user/frappe-bench/env/lib/python3.8/site-packages/redis/client.py", line 3503, in parse_response
    pubsub.get_message(ignore_subscribe_messages=True,
  File "/home/user/frappe-bench/env/lib/python3.8/site-packages/redis/client.py", line 3617, in get_message
    if not block and not conn.can_read(timeout=timeout):
  File "/home/user/frappe-bench/env/lib/python3.8/site-packages/redis/connection.py", line 734, in can_read
    response = self.parse_response(block=False, timeout=timeout)
  File "/home/user/frappe-bench/env/lib/python3.8/site-packages/redis/client.py", line 3503, in parse_response
    if not block and not conn.can_read(timeout=timeout):
  File "/home/user/frappe-bench/env/lib/python3.8/site-packages/redis/connection.py", line 734, in can_read
    return self._parser.can_read(timeout)
  File "/home/user/frappe-bench/env/lib/python3.8/site-packages/redis/connection.py", line 321, in can_read
    return self._buffer and self._buffer.can_read(timeout)
  File "/home/user/frappe-bench/env/lib/python3.8/site-packages/redis/connection.py", line 230, in can_read
    self._read_from_socket(timeout=timeout,
  File "/home/user/frappe-bench/env/lib/python3.8/site-packages/redis/connection.py", line 201, in _read_from_socket
    return self._parser.can_read(timeout)
  File "/home/user/frappe-bench/env/lib/python3.8/site-packages/redis/connection.py", line 321, in can_read
    return self._buffer and self._buffer.can_read(timeout)
  File "/home/user/frappe-bench/env/lib/python3.8/site-packages/redis/connection.py", line 230, in can_read
    self._read_from_socket(timeout=timeout,
  File "/home/user/frappe-bench/env/lib/python3.8/site-packages/redis/connection.py", line 201, in _read_from_socket
    raise ConnectionError(SERVER_CLOSED_CONNECTION_ERROR)
redis.exceptions.ConnectionError: Connection closed by server.
    raise ConnectionError(SERVER_CLOSED_CONNECTION_ERROR)
redis.exceptions.ConnectionError: Connection closed by server.
    return self._parser.can_read(timeout)
  File "/home/user/frappe-bench/env/lib/python3.8/site-packages/redis/connection.py", line 321, in can_read
    return self._buffer and self._buffer.can_read(timeout)
  File "/home/user/frappe-bench/env/lib/python3.8/site-packages/redis/connection.py", line 230, in can_read
    self._read_from_socket(timeout=timeout,
  File "/home/user/frappe-bench/env/lib/python3.8/site-packages/redis/connection.py", line 201, in _read_from_socket
    raise ConnectionError(SERVER_CLOSED_CONNECTION_ERROR)
redis.exceptions.ConnectionError: Connection closed by server.
Exception in thread Thread-1:
Traceback (most recent call last):
  File "/usr/lib/python3.8/threading.py", line 932, in _bootstrap_inner
    self.run()
  File "/home/user/frappe-bench/env/lib/python3.8/site-packages/redis/client.py", line 3718, in run
Exception in thread Thread-1:
Traceback (most recent call last):
  File "/usr/lib/python3.8/threading.py", line 932, in _bootstrap_inner
Exception in thread Thread-1:
Traceback (most recent call last):
  File "/usr/lib/python3.8/threading.py", line 932, in _bootstrap_inner
    self.run()
  File "/home/user/frappe-bench/env/lib/python3.8/site-packages/redis/client.py", line 3718, in run
    pubsub.get_message(ignore_subscribe_messages=True,
  File "/home/user/frappe-bench/env/lib/python3.8/site-packages/redis/client.py", line 3617, in get_message
    self.run()
  File "/home/user/frappe-bench/env/lib/python3.8/site-packages/redis/client.py", line 3718, in run
    pubsub.get_message(ignore_subscribe_messages=True,
  File "/home/user/frappe-bench/env/lib/python3.8/site-packages/redis/client.py", line 3617, in get_message
    response = self.parse_response(block=False, timeout=timeout)
  File "/home/user/frappe-bench/env/lib/python3.8/site-packages/redis/client.py", line 3503, in parse_response
    pubsub.get_message(ignore_subscribe_messages=True,
  File "/home/user/frappe-bench/env/lib/python3.8/site-packages/redis/client.py", line 3617, in get_message
    if not block and not conn.can_read(timeout=timeout):
  File "/home/user/frappe-bench/env/lib/python3.8/site-packages/redis/connection.py", line 734, in can_read
    response = self.parse_response(block=False, timeout=timeout)
  File "/home/user/frappe-bench/env/lib/python3.8/site-packages/redis/client.py", line 3503, in parse_response
    return self._parser.can_read(timeout)    
response = self.parse_response(block=False, timeout=timeout)  File "/home/user/frappe-bench/env/lib/python3.8/site-packages/redis/connection.py", line 321, in can_read

  File "/home/user/frappe-bench/env/lib/python3.8/site-packages/redis/client.py", line 3503, in parse_response
    return self._buffer and self._buffer.can_read(timeout)
  File "/home/user/frappe-bench/env/lib/python3.8/site-packages/redis/connection.py", line 230, in can_read
    self._read_from_socket(timeout=timeout,
  File "/home/user/frappe-bench/env/lib/python3.8/site-packages/redis/connection.py", line 201, in _read_from_socket
    raise ConnectionError(SERVER_CLOSED_CONNECTION_ERROR)
redis.exceptions.ConnectionError: Connection closed by server.
    if not block and not conn.can_read(timeout=timeout):
  File "/home/user/frappe-bench/env/lib/python3.8/site-packages/redis/connection.py", line 734, in can_read
    return self._parser.can_read(timeout)
  File "/home/user/frappe-bench/env/lib/python3.8/site-packages/redis/connection.py", line 321, in can_read
    if not block and not conn.can_read(timeout=timeout):
  File "/home/user/frappe-bench/env/lib/python3.8/site-packages/redis/connection.py", line 734, in can_read
    return self._buffer and self._buffer.can_read(timeout)
  File "/home/user/frappe-bench/env/lib/python3.8/site-packages/redis/connection.py", line 230, in can_read
    self._read_from_socket(timeout=timeout,
  File "/home/user/frappe-bench/env/lib/python3.8/site-packages/redis/connection.py", line 201, in _read_from_socket
    return self._parser.can_read(timeout)
  File "/home/user/frappe-bench/env/lib/python3.8/site-packages/redis/connection.py", line 321, in can_read
    raise ConnectionError(SERVER_CLOSED_CONNECTION_ERROR)
redis.exceptions.ConnectionError: Connection closed by server.
    return self._buffer and self._buffer.can_read(timeout)
  File "/home/user/frappe-bench/env/lib/python3.8/site-packages/redis/connection.py", line 230, in can_read
    self._read_from_socket(timeout=timeout,
  File "/home/user/frappe-bench/env/lib/python3.8/site-packages/redis/connection.py", line 201, in _read_from_socket
    raise ConnectionError(SERVER_CLOSED_CONNECTION_ERROR)
redis.exceptions.ConnectionError: Connection closed by server.
Exception in thread Exception in thread Thread-1:
Traceback (most recent call last):
Thread-1:
  File "/usr/lib/python3.8/threading.py", line 932, in _bootstrap_inner
Traceback (most recent call last):
  File "/usr/lib/python3.8/threading.py", line 932, in _bootstrap_inner
Exception in thread Thread-1:
Traceback (most recent call last):
  File "/usr/lib/python3.8/threading.py", line 932, in _bootstrap_inner
    self.run()
  File "/home/user/frappe-bench/env/lib/python3.8/site-packages/redis/client.py", line 3718, in run
    self.run()
  File "/home/user/frappe-bench/env/lib/python3.8/site-packages/redis/client.py", line 3718, in run
    pubsub.get_message(ignore_subscribe_messages=True,
  File "/home/user/frappe-bench/env/lib/python3.8/site-packages/redis/client.py", line 3617, in get_message
    pubsub.get_message(ignore_subscribe_messages=True,
  File "/home/user/frappe-bench/env/lib/python3.8/site-packages/redis/client.py", line 3617, in get_message
    response = self.parse_response(block=False, timeout=timeout)
  File "/home/user/frappe-bench/env/lib/python3.8/site-packages/redis/client.py", line 3503, in parse_response
    response = self.parse_response(block=False, timeout=timeout)
  File "/home/user/frappe-bench/env/lib/python3.8/site-packages/redis/client.py", line 3503, in parse_response
    if not block and not conn.can_read(timeout=timeout):
  File "/home/user/frappe-bench/env/lib/python3.8/site-packages/redis/connection.py", line 734, in can_read
    self.run()
  File "/home/user/frappe-bench/env/lib/python3.8/site-packages/redis/client.py", line 3718, in run
    return self._parser.can_read(timeout)
  File "/home/user/frappe-bench/env/lib/python3.8/site-packages/redis/connection.py", line 321, in can_read
    return self._buffer and self._buffer.can_read(timeout)
  File "/home/user/frappe-bench/env/lib/python3.8/site-packages/redis/connection.py", line 230, in can_read
    self._read_from_socket(timeout=timeout,
  File "/home/user/frappe-bench/env/lib/python3.8/site-packages/redis/connection.py", line 201, in _read_from_socket
    pubsub.get_message(ignore_subscribe_messages=True,
  File "/home/user/frappe-bench/env/lib/python3.8/site-packages/redis/client.py", line 3617, in get_message
    raise ConnectionError(SERVER_CLOSED_CONNECTION_ERROR)
redis.exceptions.ConnectionError: Connection closed by server.
    response = self.parse_response(block=False, timeout=timeout)
  File "/home/user/frappe-bench/env/lib/python3.8/site-packages/redis/client.py", line 3503, in parse_response
    if not block and not conn.can_read(timeout=timeout):
  File "/home/user/frappe-bench/env/lib/python3.8/site-packages/redis/connection.py", line 734, in can_read
    return self._parser.can_read(timeout)
  File "/home/user/frappe-bench/env/lib/python3.8/site-packages/redis/connection.py", line 321, in can_read
    return self._buffer and self._buffer.can_read(timeout)
  File "/home/user/frappe-bench/env/lib/python3.8/site-packages/redis/connection.py", line 230, in can_read
    self._read_from_socket(timeout=timeout,
  File "/home/user/frappe-bench/env/lib/python3.8/site-packages/redis/connection.py", line 201, in _read_from_socket
    raise ConnectionError(SERVER_CLOSED_CONNECTION_ERROR)
redis.exceptions.ConnectionError: Connection closed by server.
    if not block and not conn.can_read(timeout=timeout):
  File "/home/user/frappe-bench/env/lib/python3.8/site-packages/redis/connection.py", line 734, in can_read
    return self._parser.can_read(timeout)
  File "/home/user/frappe-bench/env/lib/python3.8/site-packages/redis/connection.py", line 321, in can_read
    return self._buffer and self._buffer.can_read(timeout)
  File "/home/user/frappe-bench/env/lib/python3.8/site-packages/redis/connection.py", line 230, in can_read
    self._read_from_socket(timeout=timeout,
  File "/home/user/frappe-bench/env/lib/python3.8/site-packages/redis/connection.py", line 201, in _read_from_socket
    raise ConnectionError(SERVER_CLOSED_CONNECTION_ERROR)
redis.exceptions.ConnectionError: Connection closed by server.
Exception in thread Thread-1:
Traceback (most recent call last):
  File "/usr/lib/python3.8/threading.py", line 932, in _bootstrap_inner
Exception in thread Thread-1:
Traceback (most recent call last):
  File "/usr/lib/python3.8/threading.py", line 932, in _bootstrap_inner
Exception in thread Thread-1:
Traceback (most recent call last):
  File "/usr/lib/python3.8/threading.py", line 932, in _bootstrap_inner
    self.run()
  File "/home/user/frappe-bench/env/lib/python3.8/site-packages/redis/client.py", line 3718, in run
    self.run()
  File "/home/user/frappe-bench/env/lib/python3.8/site-packages/redis/client.py", line 3718, in run
    self.run()
  File "/home/user/frappe-bench/env/lib/python3.8/site-packages/redis/client.py", line 3718, in run
    pubsub.get_message(ignore_subscribe_messages=True,
  File "/home/user/frappe-bench/env/lib/python3.8/site-packages/redis/client.py", line 3617, in get_message
    response = self.parse_response(block=False, timeout=timeout)
  File "/home/user/frappe-bench/env/lib/python3.8/site-packages/redis/client.py", line 3503, in parse_response
    pubsub.get_message(ignore_subscribe_messages=True,
  File "/home/user/frappe-bench/env/lib/python3.8/site-packages/redis/client.py", line 3617, in get_message
    response = self.parse_response(block=False, timeout=timeout)
  File "/home/user/frappe-bench/env/lib/python3.8/site-packages/redis/client.py", line 3503, in parse_response
    if not block and not conn.can_read(timeout=timeout):
  File "/home/user/frappe-bench/env/lib/python3.8/site-packages/redis/connection.py", line 734, in can_read
    pubsub.get_message(ignore_subscribe_messages=True,
  File "/home/user/frappe-bench/env/lib/python3.8/site-packages/redis/client.py", line 3617, in get_message
    response = self.parse_response(block=False, timeout=timeout)
  File "/home/user/frappe-bench/env/lib/python3.8/site-packages/redis/client.py", line 3503, in parse_response
    if not block and not conn.can_read(timeout=timeout):
  File "/home/user/frappe-bench/env/lib/python3.8/site-packages/redis/connection.py", line 734, in can_read
    return self._parser.can_read(timeout)
  File "/home/user/frappe-bench/env/lib/python3.8/site-packages/redis/connection.py", line 321, in can_read
    return self._buffer and self._buffer.can_read(timeout)
  File "/home/user/frappe-bench/env/lib/python3.8/site-packages/redis/connection.py", line 230, in can_read
    self._read_from_socket(timeout=timeout,
  File "/home/user/frappe-bench/env/lib/python3.8/site-packages/redis/connection.py", line 201, in _read_from_socket
    raise ConnectionError(SERVER_CLOSED_CONNECTION_ERROR)
redis.exceptions.ConnectionError: Connection closed by server.
    return self._parser.can_read(timeout)
  File "/home/user/frappe-bench/env/lib/python3.8/site-packages/redis/connection.py", line 321, in can_read
    return self._buffer and self._buffer.can_read(timeout)
  File "/home/user/frappe-bench/env/lib/python3.8/site-packages/redis/connection.py", line 230, in can_read
    self._read_from_socket(timeout=timeout,
  File "/home/user/frappe-bench/env/lib/python3.8/site-packages/redis/connection.py", line 201, in _read_from_socket
    raise ConnectionError(SERVER_CLOSED_CONNECTION_ERROR)
redis.exceptions.ConnectionError: Connection closed by server.
    if not block and not conn.can_read(timeout=timeout):
  File "/home/user/frappe-bench/env/lib/python3.8/site-packages/redis/connection.py", line 734, in can_read
    return self._parser.can_read(timeout)
  File "/home/user/frappe-bench/env/lib/python3.8/site-packages/redis/connection.py", line 321, in can_read
    return self._buffer and self._buffer.can_read(timeout)
  File "/home/user/frappe-bench/env/lib/python3.8/site-packages/redis/connection.py", line 230, in can_read
    self._read_from_socket(timeout=timeout,
  File "/home/user/frappe-bench/env/lib/python3.8/site-packages/redis/connection.py", line 201, in _read_from_socket
    raise ConnectionError(SERVER_CLOSED_CONNECTION_ERROR)
redis.exceptions.ConnectionError: Connection closed by server.
Exception in thread Thread-1:
Traceback (most recent call last):
  File "/usr/lib/python3.8/threading.py", line 932, in _bootstrap_inner
    self.run()
  File "/home/user/frappe-bench/env/lib/python3.8/site-packages/redis/client.py", line 3718, in run
  File "/home/user/frappe-bench/env/lib/python3.8/site-packages/redis/client.py", line 3617, in get_message
  File "/home/user/frappe-bench/env/lib/python3.8/site-packages/redis/client.py", line 3503, in parse_response
  File "/home/user/frappe-bench/env/lib/python3.8/site-packages/redis/connection.py", line 734, in can_read
  File "/home/user/frappe-bench/env/lib/python3.8/site-packages/redis/connection.py", line 321, in can_read
  File "/home/user/frappe-bench/env/lib/python3.8/site-packages/redis/connection.py", line 230, in can_read
  File "/home/user/frappe-bench/env/lib/python3.8/site-packages/redis/connection.py", line 201, in _read_from_socket
redis.exceptions.ConnectionError: Connection closed by server.
Exception in thread Thread-1:
Traceback (most recent call last):
  File "/usr/lib/python3.8/threading.py", line 932, in _bootstrap_inner
    self.run()
  File "/home/user/frappe-bench/env/lib/python3.8/site-packages/redis/client.py", line 3718, in run
  File "/home/user/frappe-bench/env/lib/python3.8/site-packages/redis/client.py", line 3617, in get_message
  File "/home/user/frappe-bench/env/lib/python3.8/site-packages/redis/client.py", line 3503, in parse_response
  File "/home/user/frappe-bench/env/lib/python3.8/site-packages/redis/connection.py", line 734, in can_read
  File "/home/user/frappe-bench/env/lib/python3.8/site-packages/redis/connection.py", line 321, in can_read
  File "/home/user/frappe-bench/env/lib/python3.8/site-packages/redis/connection.py", line 230, in can_read
  File "/home/user/frappe-bench/env/lib/python3.8/site-packages/redis/connection.py", line 201, in _read_from_socket
redis.exceptions.ConnectionError: Connection closed by server.
Exception in thread Thread-1:
Traceback (most recent call last):
  File "/usr/lib/python3.8/threading.py", line 932, in _bootstrap_inner
    self.run()
  File "/home/user/frappe-bench/env/lib/python3.8/site-packages/redis/client.py", line 3718, in run
  File "/home/user/frappe-bench/env/lib/python3.8/site-packages/redis/client.py", line 3617, in get_message
  File "/home/user/frappe-bench/env/lib/python3.8/site-packages/redis/client.py", line 3503, in parse_response
  File "/home/user/frappe-bench/env/lib/python3.8/site-packages/redis/connection.py", line 734, in can_read
  File "/home/user/frappe-bench/env/lib/python3.8/site-packages/redis/connection.py", line 321, in can_read
  File "/home/user/frappe-bench/env/lib/python3.8/site-packages/redis/connection.py", line 230, in can_read
  File "/home/user/frappe-bench/env/lib/python3.8/site-packages/redis/connection.py", line 201, in _read_from_socket
redis.exceptions.ConnectionError: Connection closed by server.
Exception in thread Thread-1:
Traceback (most recent call last):
  File "/usr/lib/python3.8/threading.py", line 932, in _bootstrap_inner
Traceback (most recent call last):
  File "/home/user/frappe-bench/env/lib/python3.8/site-packages/redis/connection.py", line 559, in connect
    self.run()
  File "/home/user/frappe-bench/env/lib/python3.8/site-packages/redis/client.py", line 3718, in run
    sock = self._connect()
  File "/home/user/frappe-bench/env/lib/python3.8/site-packages/redis/connection.py", line 615, in _connect
    raise err
  File "/home/user/frappe-bench/env/lib/python3.8/site-packages/redis/connection.py", line 603, in _connect
    sock.connect(socket_address)
ConnectionRefusedError: [Errno 111] Connection refused

During handling of the above exception, another exception occurred:

Traceback (most recent call last):
  File "/usr/lib/python3.8/runpy.py", line 194, in _run_module_as_main
    pubsub.get_message(ignore_subscribe_messages=True,
  File "/home/user/frappe-bench/env/lib/python3.8/site-packages/redis/client.py", line 3617, in get_message
    return _run_code(code, main_globals, None,
  File "/usr/lib/python3.8/runpy.py", line 87, in _run_code
    exec(code, run_globals)
  File "/home/user/frappe-bench/apps/frappe/frappe/utils/bench_helper.py", line 104, in <module>
    main()
  File "/home/user/frappe-bench/apps/frappe/frappe/utils/bench_helper.py", line 18, in main
    click.Group(commands=commands)(prog_name='bench')
  File "/home/user/frappe-bench/env/lib/python3.8/site-packages/click/core.py", line 829, in __call__
    return self.main(*args, **kwargs)
  File "/home/user/frappe-bench/env/lib/python3.8/site-packages/click/core.py", line 782, in main
    rv = self.invoke(ctx)
  File "/home/user/frappe-bench/env/lib/python3.8/site-packages/click/core.py", line 1259, in invoke
    response = self.parse_response(block=False, timeout=timeout)
  File "/home/user/frappe-bench/env/lib/python3.8/site-packages/redis/client.py", line 3503, in parse_response
    return _process_result(sub_ctx.command.invoke(sub_ctx))
  File "/home/user/frappe-bench/env/lib/python3.8/site-packages/click/core.py", line 1259, in invoke
    return _process_result(sub_ctx.command.invoke(sub_ctx))
  File "/home/user/frappe-bench/env/lib/python3.8/site-packages/click/core.py", line 1066, in invoke
    return ctx.invoke(self.callback, **ctx.params)
  File "/home/user/frappe-bench/env/lib/python3.8/site-packages/click/core.py", line 610, in invoke
    return callback(*args, **kwargs)
  File "/home/user/frappe-bench/apps/frappe/frappe/commands/scheduler.py", line 181, in start_worker
    start_worker(queue, quiet = quiet, rq_username=rq_username, rq_password=rq_password)
  File "/home/user/frappe-bench/apps/frappe/frappe/utils/background_jobs.py", line 158, in start_worker
    Worker(queues, name=get_worker_name(queue_name)).work(logging_level = logging_level)
  File "/home/user/frappe-bench/env/lib/python3.8/site-packages/rq/worker.py", line 627, in work
    if not block and not conn.can_read(timeout=timeout):
  File "/home/user/frappe-bench/env/lib/python3.8/site-packages/redis/connection.py", line 734, in can_read
    self.unsubscribe()
  File "/home/user/frappe-bench/env/lib/python3.8/site-packages/rq/worker.py", line 532, in unsubscribe
    return self._parser.can_read(timeout)
  File "/home/user/frappe-bench/env/lib/python3.8/site-packages/redis/connection.py", line 321, in can_read
    self.pubsub.unsubscribe()
  File "/home/user/frappe-bench/env/lib/python3.8/site-packages/redis/client.py", line 3600, in unsubscribe
    return self._buffer and self._buffer.can_read(timeout)
  File "/home/user/frappe-bench/env/lib/python3.8/site-packages/redis/connection.py", line 230, in can_read
    self._read_from_socket(timeout=timeout,
  File "/home/user/frappe-bench/env/lib/python3.8/site-packages/redis/connection.py", line 201, in _read_from_socket
    raise ConnectionError(SERVER_CLOSED_CONNECTION_ERROR)
redis.exceptions.ConnectionError: Connection closed by server.
Traceback (most recent call last):
  File "/home/user/frappe-bench/env/lib/python3.8/site-packages/redis/connection.py", line 559, in connect
    sock = self._connect()
  File "/home/user/frappe-bench/env/lib/python3.8/site-packages/redis/connection.py", line 615, in _connect
    return self.execute_command('UNSUBSCRIBE', *args)
  File "/home/user/frappe-bench/env/lib/python3.8/site-packages/redis/client.py", line 3466, in execute_command
    raise err
  File "/home/user/frappe-bench/env/lib/python3.8/site-packages/redis/connection.py", line 603, in _connect
    sock.connect(socket_address)
ConnectionRefusedError: [Errno 111] Connection refused

During handling of the above exception, another exception occurred:

Traceback (most recent call last):
  File "/usr/lib/python3.8/runpy.py", line 194, in _run_module_as_main
    return _run_code(code, main_globals, None,
  File "/usr/lib/python3.8/runpy.py", line 87, in _run_code
    exec(code, run_globals)
  File "/home/user/frappe-bench/apps/frappe/frappe/utils/bench_helper.py", line 104, in <module>
    main()
  File "/home/user/frappe-bench/apps/frappe/frappe/utils/bench_helper.py", line 18, in main
    click.Group(commands=commands)(prog_name='bench')
  File "/home/user/frappe-bench/env/lib/python3.8/site-packages/click/core.py", line 829, in __call__
    return self.main(*args, **kwargs)
  File "/home/user/frappe-bench/env/lib/python3.8/site-packages/click/core.py", line 782, in main
    rv = self.invoke(ctx)
  File "/home/user/frappe-bench/env/lib/python3.8/site-packages/click/core.py", line 1259, in invoke
    return _process_result(sub_ctx.command.invoke(sub_ctx))
  File "/home/user/frappe-bench/env/lib/python3.8/site-packages/click/core.py", line 1259, in invoke
    return _process_result(sub_ctx.command.invoke(sub_ctx))
  File "/home/user/frappe-bench/env/lib/python3.8/site-packages/click/core.py", line 1066, in invoke
    return ctx.invoke(self.callback, **ctx.params)
  File "/home/user/frappe-bench/env/lib/python3.8/site-packages/click/core.py", line 610, in invoke
    return callback(*args, **kwargs)
  File "/home/user/frappe-bench/apps/frappe/frappe/commands/scheduler.py", line 181, in start_worker
    start_worker(queue, quiet = quiet, rq_username=rq_username, rq_password=rq_password)
  File "/home/user/frappe-bench/apps/frappe/frappe/utils/background_jobs.py", line 158, in start_worker
    Worker(queues, name=get_worker_name(queue_name)).work(logging_level = logging_level)
  File "/home/user/frappe-bench/env/lib/python3.8/site-packages/rq/worker.py", line 627, in work
    self.unsubscribe()
  File "/home/user/frappe-bench/env/lib/python3.8/site-packages/rq/worker.py", line 532, in unsubscribe
    self.pubsub.unsubscribe()
  File "/home/user/frappe-bench/env/lib/python3.8/site-packages/redis/client.py", line 3600, in unsubscribe
        self.connection = self.connection_pool.get_connection(
  File "/home/user/frappe-bench/env/lib/python3.8/site-packages/redis/connection.py", line 1192, in get_connection
    connection.connect()
  File "/home/user/frappe-bench/env/lib/python3.8/site-packages/redis/connection.py", line 563, in connect
    raise ConnectionError(self._error_message(e))
redis.exceptions.ConnectionError: Error 111 connecting to localhost:11000. Connection refused.
return self.execute_command('UNSUBSCRIBE', *args)
  File "/home/user/frappe-bench/env/lib/python3.8/site-packages/redis/client.py", line 3466, in execute_command
    self.connection = self.connection_pool.get_connection(
  File "/home/user/frappe-bench/env/lib/python3.8/site-packages/redis/connection.py", line 1192, in get_connection
    connection.connect()
  File "/home/user/frappe-bench/env/lib/python3.8/site-packages/redis/connection.py", line 563, in connect
    raise ConnectionError(self._error_message(e))
redis.exceptions.ConnectionError: Error 111 connecting to localhost:11000. Connection refused.
Exception in thread Thread-1:
Traceback (most recent call last):
  File "/usr/lib/python3.8/threading.py", line 932, in _bootstrap_inner
Exception in thread Thread-1:
Traceback (most recent call last):
  File "/usr/lib/python3.8/threading.py", line 932, in _bootstrap_inner
Exception in thread Thread-1:
Traceback (most recent call last):
  File "/usr/lib/python3.8/threading.py", line 932, in _bootstrap_inner
            self.run()self.run()
self.run()

  File "/home/user/frappe-bench/env/lib/python3.8/site-packages/redis/client.py", line 3718, in run
  File "/home/user/frappe-bench/env/lib/python3.8/site-packages/redis/client.py", line 3718, in run
  File "/home/user/frappe-bench/env/lib/python3.8/site-packages/redis/client.py", line 3718, in run
    pubsub.get_message(ignore_subscribe_messages=True,    
pubsub.get_message(ignore_subscribe_messages=True,
  File "/home/user/frappe-bench/env/lib/python3.8/site-packages/redis/client.py", line 3617, in get_message
  File "/home/user/frappe-bench/env/lib/python3.8/site-packages/redis/client.py", line 3617, in get_message
    response = self.parse_response(block=False, timeout=timeout)
      File "/home/user/frappe-bench/env/lib/python3.8/site-packages/redis/client.py", line 3503, in parse_response
response = self.parse_response(block=False, timeout=timeout)
  File "/home/user/frappe-bench/env/lib/python3.8/site-packages/redis/client.py", line 3503, in parse_response
    pubsub.get_message(ignore_subscribe_messages=True,
  File "/home/user/frappe-bench/env/lib/python3.8/site-packages/redis/client.py", line 3617, in get_message
    if not block and not conn.can_read(timeout=timeout):
  File "/home/user/frappe-bench/env/lib/python3.8/site-packages/redis/connection.py", line 734, in can_read
    if not block and not conn.can_read(timeout=timeout):
  File "/home/user/frappe-bench/env/lib/python3.8/site-packages/redis/connection.py", line 734, in can_read
    response = self.parse_response(block=False, timeout=timeout)
  File "/home/user/frappe-bench/env/lib/python3.8/site-packages/redis/client.py", line 3503, in parse_response
    return self._parser.can_read(timeout)
  File "/home/user/frappe-bench/env/lib/python3.8/site-packages/redis/connection.py", line 321, in can_read
    return self._buffer and self._buffer.can_read(timeout)
  File "/home/user/frappe-bench/env/lib/python3.8/site-packages/redis/connection.py", line 230, in can_read
    self._read_from_socket(timeout=timeout,
  File "/home/user/frappe-bench/env/lib/python3.8/site-packages/redis/connection.py", line 201, in _read_from_socket
    raise ConnectionError(SERVER_CLOSED_CONNECTION_ERROR)
redis.exceptions.ConnectionError: Connection closed by server.
    if not block and not conn.can_read(timeout=timeout):
  File "/home/user/frappe-bench/env/lib/python3.8/site-packages/redis/connection.py", line 734, in can_read
    return self._parser.can_read(timeout)
  File "/home/user/frappe-bench/env/lib/python3.8/site-packages/redis/connection.py", line 321, in can_read
    return self._buffer and self._buffer.can_read(timeout)
  File "/home/user/frappe-bench/env/lib/python3.8/site-packages/redis/connection.py", line 230, in can_read
    self._read_from_socket(timeout=timeout,
  File "/home/user/frappe-bench/env/lib/python3.8/site-packages/redis/connection.py", line 201, in _read_from_socket
    raise ConnectionError(SERVER_CLOSED_CONNECTION_ERROR)
redis.exceptions.ConnectionError: Connection closed by server.
    return self._parser.can_read(timeout)
  File "/home/user/frappe-bench/env/lib/python3.8/site-packages/redis/connection.py", line 321, in can_read
    return self._buffer and self._buffer.can_read(timeout)
  File "/home/user/frappe-bench/env/lib/python3.8/site-packages/redis/connection.py", line 230, in can_read
    self._read_from_socket(timeout=timeout,
  File "/home/user/frappe-bench/env/lib/python3.8/site-packages/redis/connection.py", line 201, in _read_from_socket
    raise ConnectionError(SERVER_CLOSED_CONNECTION_ERROR)
redis.exceptions.ConnectionError: Connection closed by server.
Exception in thread Exception in thread Thread-1:
Thread-1:
Traceback (most recent call last):
Exception in thread Traceback (most recent call last):
  File "/usr/lib/python3.8/threading.py", line 932, in _bootstrap_inner
Thread-1  File "/usr/lib/python3.8/threading.py", line 932, in _bootstrap_inner
:
Traceback (most recent call last):
  File "/usr/lib/python3.8/threading.py", line 932, in _bootstrap_inner
        self.run()self.run()

  File "/home/user/frappe-bench/env/lib/python3.8/site-packages/redis/client.py", line 3718, in run
  File "/home/user/frappe-bench/env/lib/python3.8/site-packages/redis/client.py", line 3718, in run
    self.run()
  File "/home/user/frappe-bench/env/lib/python3.8/site-packages/redis/client.py", line 3718, in run
        pubsub.get_message(ignore_subscribe_messages=True,pubsub.get_message(ignore_subscribe_messages=True,

  File "/home/user/frappe-bench/env/lib/python3.8/site-packages/redis/client.py", line 3617, in get_message
  File "/home/user/frappe-bench/env/lib/python3.8/site-packages/redis/client.py", line 3617, in get_message
    pubsub.get_message(ignore_subscribe_messages=True,
  File "/home/user/frappe-bench/env/lib/python3.8/site-packages/redis/client.py", line 3617, in get_message
    response = self.parse_response(block=False, timeout=timeout)
  File "/home/user/frappe-bench/env/lib/python3.8/site-packages/redis/client.py", line 3503, in parse_response
        response = self.parse_response(block=False, timeout=timeout)response = self.parse_response(block=False, timeout=timeout)

  File "/home/user/frappe-bench/env/lib/python3.8/site-packages/redis/client.py", line 3503, in parse_response
  File "/home/user/frappe-bench/env/lib/python3.8/site-packages/redis/client.py", line 3503, in parse_response
    if not block and not conn.can_read(timeout=timeout):
  File "/home/user/frappe-bench/env/lib/python3.8/site-packages/redis/connection.py", line 734, in can_read
        if not block and not conn.can_read(timeout=timeout):if not block and not conn.can_read(timeout=timeout):

  File "/home/user/frappe-bench/env/lib/python3.8/site-packages/redis/connection.py", line 734, in can_read
  File "/home/user/frappe-bench/env/lib/python3.8/site-packages/redis/connection.py", line 734, in can_read
    return self._parser.can_read(timeout)
  File "/home/user/frappe-bench/env/lib/python3.8/site-packages/redis/connection.py", line 321, in can_read
        return self._parser.can_read(timeout)return self._parser.can_read(timeout)

  File "/home/user/frappe-bench/env/lib/python3.8/site-packages/redis/connection.py", line 321, in can_read
  File "/home/user/frappe-bench/env/lib/python3.8/site-packages/redis/connection.py", line 321, in can_read
    return self._buffer and self._buffer.can_read(timeout)
  File "/home/user/frappe-bench/env/lib/python3.8/site-packages/redis/connection.py", line 230, in can_read
    self._read_from_socket(timeout=timeout,
          File "/home/user/frappe-bench/env/lib/python3.8/site-packages/redis/connection.py", line 201, in _read_from_socket
return self._buffer and self._buffer.can_read(timeout)return self._buffer and self._buffer.can_read(timeout)

  File "/home/user/frappe-bench/env/lib/python3.8/site-packages/redis/connection.py", line 230, in can_read
  File "/home/user/frappe-bench/env/lib/python3.8/site-packages/redis/connection.py", line 230, in can_read
    raise ConnectionError(SERVER_CLOSED_CONNECTION_ERROR)
redis.exceptions.        ConnectionErrorself._read_from_socket(timeout=timeout,self._read_from_socket(timeout=timeout,

:   File "/home/user/frappe-bench/env/lib/python3.8/site-packages/redis/connection.py", line 201, in _read_from_socket
  File "/home/user/frappe-bench/env/lib/python3.8/site-packages/redis/connection.py", line 201, in _read_from_socket
Connection closed by server.
        raise ConnectionError(SERVER_CLOSED_CONNECTION_ERROR)raise ConnectionError(SERVER_CLOSED_CONNECTION_ERROR)

redis.exceptions.redis.exceptionsConnectionError.: ConnectionErrorConnection closed by server.: 
Connection closed by server.
